#VRML_SIM R2023b utf8

EXTERNPROTO "https://raw.githubusercontent.com/cyberbotics/webots/R2023b/projects/appearances/protos/Asphalt.proto"
EXTERNPROTO "https://raw.githubusercontent.com/cyberbotics/webots/R2023b/projects/objects/backgrounds/protos/TexturedBackground.proto"
EXTERNPROTO "https://raw.githubusercontent.com/cyberbotics/webots/R2023b/projects/objects/backgrounds/protos/TexturedBackgroundLight.proto"
EXTERNPROTO "https://raw.githubusercontent.com/cyberbotics/webots/R2023b/projects/objects/floors/protos/UnevenTerrain.proto"

WorldInfo {
}
Viewpoint {
  orientation -0.17857164600875444 0.27195456335392526 0.9455965750322385 1.213932376090762
  position -0.8774352144947473 -14.110428108756143 9.56004008495989
}
TexturedBackground {
}
TexturedBackgroundLight {
}
Robot {
  translation 4.829428208719386 -1.226054637650763 3.5194605203327187
  rotation 0.02501016232759027 0.04180593431435971 -0.9988126729454582 -2.891007319177102
  children [
    InertialUnit {
    }
    DEF torso Shape {
      appearance PBRAppearance {
        baseColor 0.6 0.6 1
        metalness 0
      }
      geometry Box {
        size 1 1 0.2
      }
    }
    DEF wheel HingeJoint {
      jointParameters HingeJointParameters {
        position -9.824811180826172
        axis 0 1 0
        anchor -0.3 -0.577883 -0.0631591
      }
      device [
        RotationalMotor {
          name "motor1"
        }
      ]
      endPoint Solid {
        translation -0.3 -0.577883 -0.0631591
        rotation -0.13973548527406945 0.7108936956218934 0.6892779901318967 2.8553285256923746
        children [
          DEF wheel_body Shape {
            appearance Asphalt {
            }
            geometry Cylinder {
              height 0.2
              radius 0.18
            }
          }
        ]
        boundingObject USE wheel_body
        physics DEF phy1 Physics {
          mass 1
        }
        linearVelocity -6.859550489285794e-06 -8.139241449896295e-06 -9.542884007332406e-07
        angularVelocity -9.720892109918213e-08 -7.95340727290173e-07 5.84141063157398e-07
      }
    }
    DEF wheel HingeJoint {
      jointParameters HingeJointParameters {
        position -9.828408626636612
        axis 0 1 0
        anchor 0.3 -0.577883 -0.0631591
      }
      device [
        RotationalMotor {
          name "motor2"
        }
      ]
      endPoint Solid {
        translation 0.3 -0.577883 -0.0631591
        rotation -0.14100117571562631 0.710764869310727 0.6891530809627977 2.852771355505692
        children [
          DEF wheel_body Shape {
            appearance Asphalt {
            }
            geometry Cylinder {
              height 0.2
              radius 0.18
            }
          }
        ]
        name "solid(1)"
        boundingObject USE wheel_body
        physics DEF phy1 Physics {
          mass 1
        }
        linearVelocity -6.9526257617697055e-06 -8.511323829760884e-06 -1.028179085427979e-06
        angularVelocity -8.906077101639323e-08 -7.631671275046022e-07 5.870857037626546e-07
      }
    }
    DEF wheel HingeJoint {
      jointParameters HingeJointParameters {
        position 71.27256750634436
        axis 0 1 0
        anchor 0.3 0.577883 -0.0631591
      }
      device [
        RotationalMotor {
          name "motor3"
        }
      ]
      endPoint Solid {
        translation 0.3 0.577883 -0.0631591
        rotation 0.3495739809689675 -0.6726419122558801 -0.6521893051149036 3.8336537133179576
        children [
          DEF wheel_body Shape {
            appearance Asphalt {
            }
            geometry Cylinder {
              height 0.2
              radius 0.18
            }
          }
        ]
        name "solid(2)"
        boundingObject USE wheel_body
        physics DEF phy1 Physics {
          mass 1
        }
        linearVelocity -6.219926260029144e-06 -8.687337751642221e-06 -1.145966073852658e-06
        angularVelocity -1.685099387742859e-07 -1.0750893045294022e-06 5.585323677406296e-07
      }
    }
    DEF wheel HingeJoint {
      jointParameters HingeJointParameters {
        position 71.27401708333335
        axis 0 1 0
        anchor -0.3 0.577883 -0.0631591
      }
      device [
        RotationalMotor {
          name "motor4"
        }
      ]
      endPoint Solid {
        translation -0.3 0.577883 -0.0631591
        rotation 0.34903987414429555 -0.6727848603939252 -0.6523279067172129 3.832678563440487
        children [
          DEF wheel_body Shape {
            appearance Asphalt {
            }
            geometry Cylinder {
              height 0.2
              radius 0.18
            }
          }
        ]
        name "solid(3)"
        boundingObject USE wheel_body
        physics DEF phy1 Physics {
          mass 1
        }
        linearVelocity -6.1266097572605165e-06 -8.315023287923043e-06 -1.0712124587927194e-06
        angularVelocity -2.7379364300246515e-08 -5.207549927168947e-07 6.09284782772435e-07
      }
    }
  ]
  boundingObject USE torso
  physics USE phy1
  controller "my_controller"
  linearVelocity -6.545739292096897e-06 -8.419932406969366e-06 -1.050785827942491e-06
  angularVelocity 6.808542337683068e-08 -1.4556887111018443e-07 6.436419323988773e-07
}
UnevenTerrain {
}
